Workbook

Sheet Load
A1: Id | B1: Description | C1: Brand | D1: NCC Only or Mix | E1: Flavor | F1: Form Type | G1: Pack size (# of pieces) | H1: Pack Type | I1: Shape | J1: Graphics | K1: Size Of Each Candy Piece | L1: Individually Wrapped Vs Unwrapped | M1: Single Brand/Flavor Vs Variety Of Brands/Flavors
A2: 8001 | B2: Airheads Halloween Chewy Candy Bars, Assorted, Nut Free, Regular Size, 33oz, 60 Count | C2: Airheads | D2: Non-Chocolate Candy Only | E2: Variety / Mixed Flavors (Fruity, Sour, Seasonal Flavors) | F2: Chewy | G2: Medium Multipack (40–80 ct) | H2: Box (theatre box, gift box, carton) | I2: Everyday Candy Shapes (like Original, Gummy bear, Fruit, Jewels, etc.) | J2: Seasonal Graphics (Like Bat, Ghost, Pumpkin, Fall Leaves, Eyeballs, etc.) | K2: Fun Size / Treat Size | L2: Regular/Original Wrapping | M2: Single Brand / Variety Flavors or Form
A3: 8002 | B3: AirHeads Halloween Variety Pack Candy, 0.55 oz., 90 pk. | C3: Airheads | D3: Non-Chocolate Candy Only | E3: Variety / Mixed Flavors (Fruity, Sour, Seasonal Flavors) | F3: Chewy | G3: Large Multipack (More than 80 ct) | H3: Box (theatre box, gift box, carton) | I3: Everyday Candy Shapes (like Original, Gummy bear, Fruit, Jewels, etc.) | J3: Seasonal Graphics (Like Bat, Ghost, Pumpkin, Fall Leaves, Eyeballs, etc.) | K3: Fun Size / Treat Size | L3: Regular/Original Wrapping | M3: Single Brand / Variety Flavors or Form
A4: 8003 | B4: Airheads Bites, Halloween Trick or Treat Candy, Assorted Fruit Flavors, 2 oz Packs (Box of 18 Bags) | C4: Airheads | D4: Non-Chocolate Candy Only | E4: Fruit Flavor (Cherry, Grape, Apple, Citrus, Tropical Fruit) | F4: Candy Pieces / Bites | G4: Small Multipack (Less than 40 ct) | H4: Box (theatre box, gift box, carton) | I4: Everyday Candy Shapes (like Original, Gummy bear, Fruit, Jewels, etc.) | J4: Everyday Graphics | K4: Small Pieces (Tiny bite size candies) | L4: Regular/Original Wrapping | M4: Single Brand / Variety Flavors or Form
A5: 8004 | B5: Airheads Sour Mini Halloween Candy assorted flavors, 5lb Bulk Bag | C5: Airheads | D5: Non-Chocolate Candy Only | E5: Sour | F5: Taffy | G5: Large Multipack (More than 80 ct) | H5: Laydown Bag | I5: Everyday Candy Shapes (like Original, Gummy bear, Fruit, Jewels, etc.) | J5: Everyday Graphics | K5: Fun Size / Treat Size | L5: Regular/Original Wrapping | M5: Single Brand / Variety Flavors or Form
A6: 8005 | B6: Airheads Halloween Candy Variety Bag, Individually Wrapped Assorted Fruit Mini Bars, Nut Free, 12 oz | C6: Airheads | D6: Non-Chocolate Candy Only | E6: Fruit Flavor (Cherry, Grape, Apple, Citrus, Tropical Fruit) | F6: Chewy | G6: Small Multipack (Less than 40 ct) | H6: Laydown Bag | I6: Everyday Candy Shapes (like Original, Gummy bear, Fruit, Jewels, etc.) | J6: Everyday Graphics | K6: Fun Size / Treat Size | L6: Regular/Original Wrapping | M6: Single Brand / Variety Flavors or Form
A7: 8006 | B7: Airheads Chewy Candy Variety Pack, 9 Assorted Fruit Flavored Regular Size Bars, Nut Free, 4.95 oz (2 pack) | C7: Airheads | D7: Non-Chocolate Candy Only | E7: Fruit Flavor (Cherry, Grape, Apple, Citrus, Tropical Fruit) | F7: Chewy | G7: Small Multipack (Less than 40 ct) | H7: Laydown Bag | I7: Everyday Candy Shapes (like Original, Gummy bear, Fruit, Jewels, etc.) | J7: Everyday Graphics | K7: Fun Size / Treat Size | L7: Regular/Original Wrapping | M7: Single Brand / Variety Flavors or Form
A8: 8007 | B8: Airheads Xtremes Belts Candy, Very Berry, 2 oz | C8: Airheads | D8: Non-Chocolate Candy Only | E8: Berry Based (Raspberry, Strawberry, Medley, etc.) | F8: Chewy | G8: Single Pack | H8: Laydown Bag | I8: Everyday Candy Shapes (like Original, Gummy bear, Fruit, Jewels, etc.) | J8: Everyday Graphics | K8: Fun Size / Treat Size | L8: Unwrapped | M8: Single Brand / Single Flavor or Form
A9: 8008 | B9: Airheads Candy Variety Bag, Individually Wrapped Assorted Fruit Mini Bars, Nut Free, 10 oz | C9: Airheads | D9: Non-Chocolate Candy Only | E9: Variety / Mixed Flavors (Fruity, Sour, Seasonal Flavors) | F9: Chewy | G9: Small Multipack (Less than 40 ct) | H9: Stand-Up Bag | I9: Everyday Candy Shapes (like Original, Gummy bear, Fruit, Jewels, etc.) | J9: Everyday Graphics | K9: Fun Size / Treat Size | L9: Regular/Original Wrapping | M9: Single Brand / Variety Flavors or Form
A10: 8009 | B10: Airheads Shareable Chewy Candy Bites, Assorted Fruit Flavor, Nut Free, Regular Size, 4 oz (2 pack) | C10: Airheads | D10: Non-Chocolate Candy Only | E10: Fruit Flavor (Cherry, Grape, Apple, Citrus, Tropical Fruit) | F10: Candy Pieces / Bites | G10: Small Multipack (Less than 40 ct) | H10: Laydown Bag | I10: Everyday Candy Shapes (like Original, Gummy bear, Fruit, Jewels, etc.) | J10: Everyday Graphics | K10: Small Pieces (Tiny bite size candies) | L10: Unwrapped | M10: Single Brand / Variety Flavors or Form
A11: 8010 | B11: Airheads Chewy Candy Variety Pack, 9 Sour Flavored Regular Size Bars, Nut Free, 4.95 oz (2 pack) | C11: Airheads | D11: Non-Chocolate Candy Only | E11: Sour | F11: Chewy | G11: Small Multipack (Less than 40 ct) | H11: Laydown Bag | I11: Everyday Candy Shapes (like Original, Gummy bear, Fruit, Jewels, etc.) | J11: Everyday Graphics | K11: Fun Size / Treat Size | L11: Regular/Original Wrapping | M11: Single Brand / Variety Flavors or Form
A12: 8011 | B12: Albanese World's Best, Halloween 12 Flavor Gummi Bear Cubs®, 50-0.5oz Trick or Treat Bags of Halloween Candy | C12: Albanese | D12: Non-Chocolate Candy Only | E12: Sweet | F12: Gummy | G12: Single Pack | H12: Laydown Bag | I12: Everyday Candy Shapes (like Original, Gummy bear, Fruit, Jewels, etc.) | J12: Seasonal Graphics (Like Bat, Ghost, Pumpkin, Fall Leaves, Eyeballs, etc.) | K12: Small Pieces (Tiny bite size candies) | L12: Regular/Original Wrapping | M12: Single Brand / Variety Flavors or Form
A13: 8012 | B13: Albanese Sweet & Sour Monster Combo 16ct Trick-or-Treat Bag of Halloween Candy | C13: Albanese | D13: Non-Chocolate Candy Only | E13: Variety / Mixed Flavors (Fruity, Sour, Seasonal Flavors) | F13: Gummy | G13: Single Pack | H13: Laydown Bag | I13: Everyday Candy Shapes (like Original, Gummy bear, Fruit, Jewels, etc.) | J13: Seasonal Graphics (Like Bat, Ghost, Pumpkin, Fall Leaves, Eyeballs, etc.) | K13: Small Pieces (Tiny bite size candies) | L13: Regular/Original Wrapping | M13: Single Brand / Variety Flavors or Form
... A357: 9999 | B357: z-I wouldn’t substitute anything | C357: I wouldn’t substitute anything | D357: I wouldn’t substitute anything | E357: I wouldn’t substitute anything | F357: I wouldn’t substitute anything | G357: I wouldn’t substitute anything | H357: I wouldn’t substitute anything | I357: I wouldn’t substitute anything | J357: I wouldn’t substitute anything | K357: I wouldn’t substitute anything | L357: I wouldn’t substitute anything | M357: I wouldn’t substitute anything

Sheet Sheet1
A1: HidProduct | B1: Brand | C1: CandyMixStacked | D1: FlavorStacked | E1: FormTypeStacked | F1: PackSizeStacked | G1: PackTypeStacked | H1: ShapeStacked | I1: GraphicsStacked | J1: SizeOfEachCandyPiecesStacked | K1: IndividuallyWrappedVsUnwrappedStacked | L1: SingleBrand/FlavorVsVarietyOfBrands/FlavorsStacked
A2: Flix Candy Beetlejuice Gummies, 22 Count Resealable Laydown Bag, Halloween Candy | B2: =_xlfn.XLOOKUP($A2,Load!$B:$B,Load!C:C,0,) -> Flix | C2: =_xlfn.XLOOKUP($A2,Load!$B:$B,Load!D:D,0,) -> Non-Chocolate Candy Only | D2: =_xlfn.XLOOKUP($A2,Load!$B:$B,Load!E:E,0,) -> Fruit Flavor (Cherry, Grape, Apple, Citrus, Tropical Fruit) | E2: =_xlfn.XLOOKUP($A2,Load!$B:$B,Load!F:F,0,) -> Gummy | F2: =_xlfn.XLOOKUP($A2,Load!$B:$B,Load!G:G,0,) -> Small Multipack (Less than 40 ct) | G2: =_xlfn.XLOOKUP($A2,Load!$B:$B,Load!H:H,0,) -> Laydown Bag | H2: =_xlfn.XLOOKUP($A2,Load!$B:$B,Load!I:I,0,) -> Seasonal Shapes (like pumpkins, candy corn, ghost, bats, etc.) | I2: =_xlfn.XLOOKUP($A2,Load!$B:$B,Load!J:J,0,) -> Seasonal Graphics (Like Bat, Ghost, Pumpkin, Fall Leaves, Eyeballs, etc.) | J2: =_xlfn.XLOOKUP($A2,Load!$B:$B,Load!K:K,0,) -> Small Pieces (Tiny bite size candies) | K2: =_xlfn.XLOOKUP($A2,Load!$B:$B,Load!L:L,0,) -> Regular/Original Wrapping | L2: =_xlfn.XLOOKUP($A2,Load!$B:$B,Load!M:M,0,) -> Single Brand / Variety Flavors or Form
B3: =_xlfn.XLOOKUP($A3,Load!$B:$B,Load!C:C,0,) -> 0 | C3: =_xlfn.XLOOKUP($A3,Load!$B:$B,Load!D:D,0,) -> 0 | D3: =_xlfn.XLOOKUP($A3,Load!$B:$B,Load!E:E,0,) -> 0 | E3: =_xlfn.XLOOKUP($A3,Load!$B:$B,Load!F:F,0,) -> 0 | F3: =_xlfn.XLOOKUP($A3,Load!$B:$B,Load!G:G,0,) -> 0 | G3: =_xlfn.XLOOKUP($A3,Load!$B:$B,Load!H:H,0,) -> 0 | H3: =_xlfn.XLOOKUP($A3,Load!$B:$B,Load!I:I,0,) -> 0 | I3: =_xlfn.XLOOKUP($A3,Load!$B:$B,Load!J:J,0,) -> 0 | J3: =_xlfn.XLOOKUP($A3,Load!$B:$B,Load!K:K,0,) -> 0 | K3: =_xlfn.XLOOKUP($A3,Load!$B:$B,Load!L:L,0,) -> 0 | L3: =_xlfn.XLOOKUP($A3,Load!$B:$B,Load!M:M,0,) -> 0
A4: M&M's, Snickers, 3 Musketeers, Skittles & Starburst Variety Pack Full Size Candy Assortment - 30 Bars | B4: =_xlfn.XLOOKUP($A4,Load!$B:$B,Load!C:C,0,) -> Mars Variety Pack | C4: =_xlfn.XLOOKUP($A4,Load!$B:$B,Load!D:D,0,) -> Mix of Chocolate and Non-Chocolate Candy | D4: =_xlfn.XLOOKUP($A4,Load!$B:$B,Load!E:E,0,) -> Variety / Mixed Flavors (Fruity, Sour, Seasonal Flavors) | E4: =_xlfn.XLOOKUP($A4,Load!$B:$B,Load!F:F,0,) -> Mixed / Combo Packs (Gummy, Chewy, Taffy, etc.) | F4: =_xlfn.XLOOKUP($A4,Load!$B:$B,Load!G:G,0,) -> Small Multipack (Less than 40 ct) | G4: =_xlfn.XLOOKUP($A4,Load!$B:$B,Load!H:H,0,) -> Box (theatre box, gift box, carton) | H4: =_xlfn.XLOOKUP($A4,Load!$B:$B,Load!I:I,0,) -> Everyday Candy Shapes (like Original, Gummy bear, Fruit, Jewels, etc.) | I4: =_xlfn.XLOOKUP($A4,Load!$B:$B,Load!J:J,0,) -> Everyday Graphics | J4: =_xlfn.XLOOKUP($A4,Load!$B:$B,Load!K:K,0,) -> Fun Size / Treat Size | K4: =_xlfn.XLOOKUP($A4,Load!$B:$B,Load!L:L,0,) -> Regular/Original Wrapping | L4: =_xlfn.XLOOKUP($A4,Load!$B:$B,Load!M:M,0,) -> Multiple Brands / Variety Flavors or Form
B5: =_xlfn.XLOOKUP($A5,Load!$B:$B,Load!C:C,0,) -> 0 | C5: =_xlfn.XLOOKUP($A5,Load!$B:$B,Load!D:D,0,) -> 0 | D5: =_xlfn.XLOOKUP($A5,Load!$B:$B,Load!E:E,0,) -> 0 | E5: =_xlfn.XLOOKUP($A5,Load!$B:$B,Load!F:F,0,) -> 0 | F5: =_xlfn.XLOOKUP($A5,Load!$B:$B,Load!G:G,0,) -> 0 | G5: =_xlfn.XLOOKUP($A5,Load!$B:$B,Load!H:H,0,) -> 0 | H5: =_xlfn.XLOOKUP($A5,Load!$B:$B,Load!I:I,0,) -> 0 | I5: =_xlfn.XLOOKUP($A5,Load!$B:$B,Load!J:J,0,) -> 0 | J5: =_xlfn.XLOOKUP($A5,Load!$B:$B,Load!K:K,0,) -> 0 | K5: =_xlfn.XLOOKUP($A5,Load!$B:$B,Load!L:L,0,) -> 0 | L5: =_xlfn.XLOOKUP($A5,Load!$B:$B,Load!M:M,0,) -> 0
A6: Trolli Mini Sour Brite Crawlers, Halloween Sour Candy Treat Sized, Trick-or-Treating and Fall Parties, 9.6 oz Bag, 16 Co | B6: =_xlfn.XLOOKUP($A6,Load!$B:$B,Load!C:C,0,) -> Trolli | C6: =_xlfn.XLOOKUP($A6,Load!$B:$B,Load!D:D,0,) -> Non-Chocolate Candy Only | D6: =_xlfn.XLOOKUP($A6,Load!$B:$B,Load!E:E,0,) -> Sour | E6: =_xlfn.XLOOKUP($A6,Load!$B:$B,Load!F:F,0,) -> Gummy | F6: =_xlfn.XLOOKUP($A6,Load!$B:$B,Load!G:G,0,) -> Small Multipack (Less than 40 ct) | G6: =_xlfn.XLOOKUP($A6,Load!$B:$B,Load!H:H,0,) -> Laydown Bag | H6: =_xlfn.XLOOKUP($A6,Load!$B:$B,Load!I:I,0,) -> Seasonal Shapes (like pumpkins, candy corn, ghost, bats, etc.) | I6: =_xlfn.XLOOKUP($A6,Load!$B:$B,Load!J:J,0,) -> Seasonal Graphics (Like Bat, Ghost, Pumpkin, Fall Leaves, Eyeballs, etc.) | J6: =_xlfn.XLOOKUP($A6,Load!$B:$B,Load!K:K,0,) -> Fun Size / Treat Size | K6: =_xlfn.XLOOKUP($A6,Load!$B:$B,Load!L:L,0,) -> Regular/Original Wrapping | L6: =_xlfn.XLOOKUP($A6,Load!$B:$B,Load!M:M,0,) -> Single Brand / Variety Flavors or Form
B7: =_xlfn.XLOOKUP($A7,Load!$B:$B,Load!C:C,0,) -> 0 | C7: =_xlfn.XLOOKUP($A7,Load!$B:$B,Load!D:D,0,) -> 0 | D7: =_xlfn.XLOOKUP($A7,Load!$B:$B,Load!E:E,0,) -> 0 | E7: =_xlfn.XLOOKUP($A7,Load!$B:$B,Load!F:F,0,) -> 0 | F7: =_xlfn.XLOOKUP($A7,Load!$B:$B,Load!G:G,0,) -> 0 | G7: =_xlfn.XLOOKUP($A7,Load!$B:$B,Load!H:H,0,) -> 0 | H7: =_xlfn.XLOOKUP($A7,Load!$B:$B,Load!I:I,0,) -> 0 | I7: =_xlfn.XLOOKUP($A7,Load!$B:$B,Load!J:J,0,) -> 0 | J7: =_xlfn.XLOOKUP($A7,Load!$B:$B,Load!K:K,0,) -> 0 | K7: =_xlfn.XLOOKUP($A7,Load!$B:$B,Load!L:L,0,) -> 0 | L7: =_xlfn.XLOOKUP($A7,Load!$B:$B,Load!M:M,0,) -> 0
B8: =_xlfn.XLOOKUP($A8,Load!$B:$B,Load!C:C,0,) -> 0 | C8: =_xlfn.XLOOKUP($A8,Load!$B:$B,Load!D:D,0,) -> 0 | D8: =_xlfn.XLOOKUP($A8,Load!$B:$B,Load!E:E,0,) -> 0 | E8: =_xlfn.XLOOKUP($A8,Load!$B:$B,Load!F:F,0,) -> 0 | F8: =_xlfn.XLOOKUP($A8,Load!$B:$B,Load!G:G,0,) -> 0 | G8: =_xlfn.XLOOKUP($A8,Load!$B:$B,Load!H:H,0,) -> 0 | H8: =_xlfn.XLOOKUP($A8,Load!$B:$B,Load!I:I,0,) -> 0 | I8: =_xlfn.XLOOKUP($A8,Load!$B:$B,Load!J:J,0,) -> 0 | J8: =_xlfn.XLOOKUP($A8,Load!$B:$B,Load!K:K,0,) -> 0 | K8: =_xlfn.XLOOKUP($A8,Load!$B:$B,Load!L:L,0,) -> 0 | L8: =_xlfn.XLOOKUP($A8,Load!$B:$B,Load!M:M,0,) -> 0
B9: =_xlfn.XLOOKUP($A9,Load!$B:$B,Load!C:C,0,) -> 0 | C9: =_xlfn.XLOOKUP($A9,Load!$B:$B,Load!D:D,0,) -> 0 | D9: =_xlfn.XLOOKUP($A9,Load!$B:$B,Load!E:E,0,) -> 0 | E9: =_xlfn.XLOOKUP($A9,Load!$B:$B,Load!F:F,0,) -> 0 | F9: =_xlfn.XLOOKUP($A9,Load!$B:$B,Load!G:G,0,) -> 0 | G9: =_xlfn.XLOOKUP($A9,Load!$B:$B,Load!H:H,0,) -> 0 | H9: =_xlfn.XLOOKUP($A9,Load!$B:$B,Load!I:I,0,) -> 0 | I9: =_xlfn.XLOOKUP($A9,Load!$B:$B,Load!J:J,0,) -> 0 | J9: =_xlfn.XLOOKUP($A9,Load!$B:$B,Load!K:K,0,) -> 0 | K9: =_xlfn.XLOOKUP($A9,Load!$B:$B,Load!L:L,0,) -> 0 | L9: =_xlfn.XLOOKUP($A9,Load!$B:$B,Load!M:M,0,) -> 0
A10: Mars Assorted M&M'S, SNICKERS, SKITTLES, STARBURST Halloween Pack 18.5 Oz 40 Ct | B10: =_xlfn.XLOOKUP($A10,Load!$B:$B,Load!C:C,0,) -> Mars Variety Pack | C10: =_xlfn.XLOOKUP($A10,Load!$B:$B,Load!D:D,0,) -> Mix of Chocolate and Non-Chocolate Candy | D10: =_xlfn.XLOOKUP($A10,Load!$B:$B,Load!E:E,0,) -> Variety / Mixed Flavors (Fruity, Sour, Seasonal Flavors) | E10: =_xlfn.XLOOKUP($A10,Load!$B:$B,Load!F:F,0,) -> Mixed / Combo Packs (Gummy, Chewy, Taffy, etc.) | F10: =_xlfn.XLOOKUP($A10,Load!$B:$B,Load!G:G,0,) -> Medium Multipack (40–80 ct) | G10: =_xlfn.XLOOKUP($A10,Load!$B:$B,Load!H:H,0,) -> Stand-Up Bag | H10: =_xlfn.XLOOKUP($A10,Load!$B:$B,Load!I:I,0,) -> Everyday Candy Shapes (like Original, Gummy bear, Fruit, Jewels, etc.) | I10: =_xlfn.XLOOKUP($A10,Load!$B:$B,Load!J:J,0,) -> Seasonal Graphics (Like Bat, Ghost, Pumpkin, Fall Leaves, Eyeballs, etc.) | J10: =_xlfn.XLOOKUP($A10,Load!$B:$B,Load!K:K,0,) -> Fun Size / Treat Size | K10: =_xlfn.XLOOKUP($A10,Load!$B:$B,Load!L:L,0,) -> Regular/Original Wrapping | L10: =_xlfn.XLOOKUP($A10,Load!$B:$B,Load!M:M,0,) -> Multiple Brands / Variety Flavors or Form
A11: Mars Halloween Mixed Assorted Chocolate & Hard Candy, 21.75 oz, Bag 21.75 Oz 55 Ct | B11: =_xlfn.XLOOKUP($A11,Load!$B:$B,Load!C:C,0,) -> Mars Variety Pack | C11: =_xlfn.XLOOKUP($A11,Load!$B:$B,Load!D:D,0,) -> Mix of Chocolate and Non-Chocolate Candy | D11: =_xlfn.XLOOKUP($A11,Load!$B:$B,Load!E:E,0,) -> Variety / Mixed Flavors (Fruity, Sour, Seasonal Flavors) | E11: =_xlfn.XLOOKUP($A11,Load!$B:$B,Load!F:F,0,) -> Mixed / Combo Packs (Gummy, Chewy, Taffy, etc.) | F11: =_xlfn.XLOOKUP($A11,Load!$B:$B,Load!G:G,0,) -> Medium Multipack (40–80 ct) | G11: =_xlfn.XLOOKUP($A11,Load!$B:$B,Load!H:H,0,) -> Stand-Up Bag | H11: =_xlfn.XLOOKUP($A11,Load!$B:$B,Load!I:I,0,) -> Everyday Candy Shapes (like Original, Gummy bear, Fruit, Jewels, etc.) | I11: =_xlfn.XLOOKUP($A11,Load!$B:$B,Load!J:J,0,) -> Seasonal Graphics (Like Bat, Ghost, Pumpkin, Fall Leaves, Eyeballs, etc.) | J11: =_xlfn.XLOOKUP($A11,Load!$B:$B,Load!K:K,0,) -> Fun Size / Treat Size | K11: =_xlfn.XLOOKUP($A11,Load!$B:$B,Load!L:L,0,) -> Regular/Original Wrapping | L11: =_xlfn.XLOOKUP($A11,Load!$B:$B,Load!M:M,0,) -> Multiple Brands / Variety Flavors or Form
B12: =_xlfn.XLOOKUP($A12,Load!$B:$B,Load!C:C,0,) -> 0 | C12: =_xlfn.XLOOKUP($A12,Load!$B:$B,Load!D:D,0,) -> 0 | D12: =_xlfn.XLOOKUP($A12,Load!$B:$B,Load!E:E,0,) -> 0 | E12: =_xlfn.XLOOKUP($A12,Load!$B:$B,Load!F:F,0,) -> 0 | F12: =_xlfn.XLOOKUP($A12,Load!$B:$B,Load!G:G,0,) -> 0 | G12: =_xlfn.XLOOKUP($A12,Load!$B:$B,Load!H:H,0,) -> 0 | H12: =_xlfn.XLOOKUP($A12,Load!$B:$B,Load!I:I,0,) -> 0 | I12: =_xlfn.XLOOKUP($A12,Load!$B:$B,Load!J:J,0,) -> 0 | J12: =_xlfn.XLOOKUP($A12,Load!$B:$B,Load!K:K,0,) -> 0 | K12: =_xlfn.XLOOKUP($A12,Load!$B:$B,Load!L:L,0,) -> 0 | L12: =_xlfn.XLOOKUP($A12,Load!$B:$B,Load!M:M,0,) -> 0
B13: =_xlfn.XLOOKUP($A13,Load!$B:$B,Load!C:C,0,) -> 0 | C13: =_xlfn.XLOOKUP($A13,Load!$B:$B,Load!D:D,0,) -> 0 | D13: =_xlfn.XLOOKUP($A13,Load!$B:$B,Load!E:E,0,) -> 0 | E13: =_xlfn.XLOOKUP($A13,Load!$B:$B,Load!F:F,0,) -> 0 | F13: =_xlfn.XLOOKUP($A13,Load!$B:$B,Load!G:G,0,) -> 0 | G13: =_xlfn.XLOOKUP($A13,Load!$B:$B,Load!H:H,0,) -> 0 | H13: =_xlfn.XLOOKUP($A13,Load!$B:$B,Load!I:I,0,) -> 0 | I13: =_xlfn.XLOOKUP($A13,Load!$B:$B,Load!J:J,0,) -> 0 | J13: =_xlfn.XLOOKUP($A13,Load!$B:$B,Load!K:K,0,) -> 0 | K13: =_xlfn.XLOOKUP($A13,Load!$B:$B,Load!L:L,0,) -> 0 | L13: =_xlfn.XLOOKUP($A13,Load!$B:$B,Load!M:M,0,) -> 0
B14: =_xlfn.XLOOKUP($A14,Load!$B:$B,Load!C:C,0,) -> 0 | C14: =_xlfn.XLOOKUP($A14,Load!$B:$B,Load!D:D,0,) -> 0 | D14: =_xlfn.XLOOKUP($A14,Load!$B:$B,Load!E:E,0,) -> 0 | E14: =_xlfn.XLOOKUP($A14,Load!$B:$B,Load!F:F,0,) -> 0 | F14: =_xlfn.XLOOKUP($A14,Load!$B:$B,Load!G:G,0,) -> 0 | G14: =_xlfn.XLOOKUP($A14,Load!$B:$B,Load!H:H,0,) -> 0 | H14: =_xlfn.XLOOKUP($A14,Load!$B:$B,Load!I:I,0,) -> 0 | I14: =_xlfn.XLOOKUP($A14,Load!$B:$B,Load!J:J,0,) -> 0 | J14: =_xlfn.XLOOKUP($A14,Load!$B:$B,Load!K:K,0,) -> 0 | K14: =_xlfn.XLOOKUP($A14,Load!$B:$B,Load!L:L,0,) -> 0 | L14: =_xlfn.XLOOKUP($A14,Load!$B:$B,Load!M:M,0,) -> 0
B15: =_xlfn.XLOOKUP($A15,Load!$B:$B,Load!C:C,0,) -> 0 | C15: =_xlfn.XLOOKUP($A15,Load!$B:$B,Load!D:D,0,) -> 0 | D15: =_xlfn.XLOOKUP($A15,Load!$B:$B,Load!E:E,0,) -> 0 | E15: =_xlfn.XLOOKUP($A15,Load!$B:$B,Load!F:F,0,) -> 0 | F15: =_xlfn.XLOOKUP($A15,Load!$B:$B,Load!G:G,0,) -> 0 | G15: =_xlfn.XLOOKUP($A15,Load!$B:$B,Load!H:H,0,) -> 0 | H15: =_xlfn.XLOOKUP($A15,Load!$B:$B,Load!I:I,0,) -> 0 | I15: =_xlfn.XLOOKUP($A15,Load!$B:$B,Load!J:J,0,) -> 0 | J15: =_xlfn.XLOOKUP($A15,Load!$B:$B,Load!K:K,0,) -> 0 | K15: =_xlfn.XLOOKUP($A15,Load!$B:$B,Load!L:L,0,) -> 0 | L15: =_xlfn.XLOOKUP($A15,Load!$B:$B,Load!M:M,0,) -> 0
A16: HARIBO Happy House Mix Halloween Assorted Fruit Flavor and Shapes Gummy Candy, 32oz Bag, 80ct Mini Gummy Pouches | B16: =_xlfn.XLOOKUP($A16,Load!$B:$B,Load!C:C,0,) -> HARIBO | C16: =_xlfn.XLOOKUP($A16,Load!$B:$B,Load!D:D,0,) -> Non-Chocolate Candy Only | D16: =_xlfn.XLOOKUP($A16,Load!$B:$B,Load!E:E,0,) -> Variety / Mixed Flavors (Fruity, Sour, Seasonal Flavors) | E16: =_xlfn.XLOOKUP($A16,Load!$B:$B,Load!F:F,0,) -> Gummy | F16: =_xlfn.XLOOKUP($A16,Load!$B:$B,Load!G:G,0,) -> Medium Multipack (40–80 ct) | G16: =_xlfn.XLOOKUP($A16,Load!$B:$B,Load!H:H,0,) -> Laydown Bag | H16: =_xlfn.XLOOKUP($A16,Load!$B:$B,Load!I:I,0,) -> Seasonal Shapes (like pumpkins, candy corn, ghost, bats, etc.) | I16: =_xlfn.XLOOKUP($A16,Load!$B:$B,Load!J:J,0,) -> Seasonal Graphics (Like Bat, Ghost, Pumpkin, Fall Leaves, Eyeballs, etc.) | J16: =_xlfn.XLOOKUP($A16,Load!$B:$B,Load!K:K,0,) -> Small Pieces (Tiny bite size candies) | K16: =_xlfn.XLOOKUP($A16,Load!$B:$B,Load!L:L,0,) -> Regular/Original Wrapping | L16: =_xlfn.XLOOKUP($A16,Load!$B:$B,Load!M:M,0,) -> Multiple Brands / Variety Flavors or Form
B17: =_xlfn.XLOOKUP($A17,Load!$B:$B,Load!C:C,0,) -> 0 | C17: =_xlfn.XLOOKUP($A17,Load!$B:$B,Load!D:D,0,) -> 0 | D17: =_xlfn.XLOOKUP($A17,Load!$B:$B,Load!E:E,0,) -> 0 | E17: =_xlfn.XLOOKUP($A17,Load!$B:$B,Load!F:F,0,) -> 0 | F17: =_xlfn.XLOOKUP($A17,Load!$B:$B,Load!G:G,0,) -> 0 | G17: =_xlfn.XLOOKUP($A17,Load!$B:$B,Load!H:H,0,) -> 0 | H17: =_xlfn.XLOOKUP($A17,Load!$B:$B,Load!I:I,0,) -> 0 | I17: =_xlfn.XLOOKUP($A17,Load!$B:$B,Load!J:J,0,) -> 0 | J17: =_xlfn.XLOOKUP($A17,Load!$B:$B,Load!K:K,0,) -> 0 | K17: =_xlfn.XLOOKUP($A17,Load!$B:$B,Load!L:L,0,) -> 0 | L17: =_xlfn.XLOOKUP($A17,Load!$B:$B,Load!M:M,0,) -> 0
B18: =_xlfn.XLOOKUP($A18,Load!$B:$B,Load!C:C,0,) -> 0 | C18: =_xlfn.XLOOKUP($A18,Load!$B:$B,Load!D:D,0,) -> 0 | D18: =_xlfn.XLOOKUP($A18,Load!$B:$B,Load!E:E,0,) -> 0 | E18: =_xlfn.XLOOKUP($A18,Load!$B:$B,Load!F:F,0,) -> 0 | F18: =_xlfn.XLOOKUP($A18,Load!$B:$B,Load!G:G,0,) -> 0 | G18: =_xlfn.XLOOKUP($A18,Load!$B:$B,Load!H:H,0,) -> 0 | H18: =_xlfn.XLOOKUP($A18,Load!$B:$B,Load!I:I,0,) -> 0 | I18: =_xlfn.XLOOKUP($A18,Load!$B:$B,Load!J:J,0,) -> 0 | J18: =_xlfn.XLOOKUP($A18,Load!$B:$B,Load!K:K,0,) -> 0 | K18: =_xlfn.XLOOKUP($A18,Load!$B:$B,Load!L:L,0,) -> 0 | L18: =_xlfn.XLOOKUP($A18,Load!$B:$B,Load!M:M,0,) -> 0
B19: =_xlfn.XLOOKUP($A19,Load!$B:$B,Load!C:C,0,) -> 0 | C19: =_xlfn.XLOOKUP($A19,Load!$B:$B,Load!D:D,0,) -> 0 | D19: =_xlfn.XLOOKUP($A19,Load!$B:$B,Load!E:E,0,) -> 0 | E19: =_xlfn.XLOOKUP($A19,Load!$B:$B,Load!F:F,0,) -> 0 | F19: =_xlfn.XLOOKUP($A19,Load!$B:$B,Load!G:G,0,) -> 0 | G19: =_xlfn.XLOOKUP($A19,Load!$B:$B,Load!H:H,0,) -> 0 | H19: =_xlfn.XLOOKUP($A19,Load!$B:$B,Load!I:I,0,) -> 0 | I19: =_xlfn.XLOOKUP($A19,Load!$B:$B,Load!J:J,0,) -> 0 | J19: =_xlfn.XLOOKUP($A19,Load!$B:$B,Load!K:K,0,) -> 0 | K19: =_xlfn.XLOOKUP($A19,Load!$B:$B,Load!L:L,0,) -> 0 | L19: =_xlfn.XLOOKUP($A19,Load!$B:$B,Load!M:M,0,) -> 0
A20: Mars Halloween Variety Pack Candy, Mini & Fun Size, 185 pcs. | B20: =_xlfn.XLOOKUP($A20,Load!$B:$B,Load!C:C,0,) -> Mars Variety Pack | C20: =_xlfn.XLOOKUP($A20,Load!$B:$B,Load!D:D,0,) -> Mix of Chocolate and Non-Chocolate Candy | D20: =_xlfn.XLOOKUP($A20,Load!$B:$B,Load!E:E,0,) -> Variety / Mixed Flavors (Fruity, Sour, Seasonal Flavors) | E20: =_xlfn.XLOOKUP($A20,Load!$B:$B,Load!F:F,0,) -> Mixed / Combo Packs (Gummy, Chewy, Taffy, etc.) | F20: =_xlfn.XLOOKUP($A20,Load!$B:$B,Load!G:G,0,) -> Large Multipack (More than 80 ct) | G20: =_xlfn.XLOOKUP($A20,Load!$B:$B,Load!H:H,0,) -> Stand-Up Bag | H20: =_xlfn.XLOOKUP($A20,Load!$B:$B,Load!I:I,0,) -> Everyday Candy Shapes (like Original, Gummy bear, Fruit, Jewels, etc.) | I20: =_xlfn.XLOOKUP($A20,Load!$B:$B,Load!J:J,0,) -> Seasonal Graphics (Like Bat, Ghost, Pumpkin, Fall Leaves, Eyeballs, etc.) | J20: =_xlfn.XLOOKUP($A20,Load!$B:$B,Load!K:K,0,) -> Fun Size / Treat Size | K20: =_xlfn.XLOOKUP($A20,Load!$B:$B,Load!L:L,0,) -> Regular/Original Wrapping | L20: =_xlfn.XLOOKUP($A20,Load!$B:$B,Load!M:M,0,) -> Multiple Brands / Variety Flavors or Form
B21: =_xlfn.XLOOKUP($A21,Load!$B:$B,Load!C:C,0,) -> 0 | C21: =_xlfn.XLOOKUP($A21,Load!$B:$B,Load!D:D,0,) -> 0 | D21: =_xlfn.XLOOKUP($A21,Load!$B:$B,Load!E:E,0,) -> 0 | E21: =_xlfn.XLOOKUP($A21,Load!$B:$B,Load!F:F,0,) -> 0 | F21: =_xlfn.XLOOKUP($A21,Load!$B:$B,Load!G:G,0,) -> 0 | G21: =_xlfn.XLOOKUP($A21,Load!$B:$B,Load!H:H,0,) -> 0 | H21: =_xlfn.XLOOKUP($A21,Load!$B:$B,Load!I:I,0,) -> 0 | I21: =_xlfn.XLOOKUP($A21,Load!$B:$B,Load!J:J,0,) -> 0 | J21: =_xlfn.XLOOKUP($A21,Load!$B:$B,Load!K:K,0,) -> 0 | K21: =_xlfn.XLOOKUP($A21,Load!$B:$B,Load!L:L,0,) -> 0 | L21: =_xlfn.XLOOKUP($A21,Load!$B:$B,Load!M:M,0,) -> 0
A22: Starburst, Life Savers & Hubba Bubba Halloween Candy Variety Pack - 190 Ct Bulk Bag | B22: =_xlfn.XLOOKUP($A22,Load!$B:$B,Load!C:C,0,) -> Mars Variety Pack | C22: =_xlfn.XLOOKUP($A22,Load!$B:$B,Load!D:D,0,) -> Non-Chocolate Candy Only | D22: =_xlfn.XLOOKUP($A22,Load!$B:$B,Load!E:E,0,) -> Variety / Mixed Flavors (Fruity, Sour, Seasonal Flavors) | E22: =_xlfn.XLOOKUP($A22,Load!$B:$B,Load!F:F,0,) -> Mixed / Combo Packs (Gummy, Chewy, Taffy, etc.) | F22: =_xlfn.XLOOKUP($A22,Load!$B:$B,Load!G:G,0,) -> Large Multipack (More than 80 ct) | G22: =_xlfn.XLOOKUP($A22,Load!$B:$B,Load!H:H,0,) -> Stand-Up Bag | H22: =_xlfn.XLOOKUP($A22,Load!$B:$B,Load!I:I,0,) -> Everyday Candy Shapes (like Original, Gummy bear, Fruit, Jewels, etc.) | I22: =_xlfn.XLOOKUP($A22,Load!$B:$B,Load!J:J,0,) -> Seasonal Graphics (Like Bat, Ghost, Pumpkin, Fall Leaves, Eyeballs, etc.) | J22: =_xlfn.XLOOKUP($A22,Load!$B:$B,Load!K:K,0,) -> Variety Candy Sizes | K22: =_xlfn.XLOOKUP($A22,Load!$B:$B,Load!L:L,0,) -> Regular/Original Wrapping | L22: =_xlfn.XLOOKUP($A22,Load!$B:$B,Load!M:M,0,) -> Multiple Brands / Variety Flavors or Form
A23: Starburst, Life Savers & Hubba Bubba Halloween Candy Variety - 255 Ct Bulk Bag | B23: =_xlfn.XLOOKUP($A23,Load!$B:$B,Load!C:C,0,) -> Mars Variety Pack | C23: =_xlfn.XLOOKUP($A23,Load!$B:$B,Load!D:D,0,) -> Non-Chocolate Candy Only | D23: =_xlfn.XLOOKUP($A23,Load!$B:$B,Load!E:E,0,) -> Variety / Mixed Flavors (Fruity, Sour, Seasonal Flavors) | E23: =_xlfn.XLOOKUP($A23,Load!$B:$B,Load!F:F,0,) -> Mixed / Combo Packs (Gummy, Chewy, Taffy, etc.) | F23: =_xlfn.XLOOKUP($A23,Load!$B:$B,Load!G:G,0,) -> Large Multipack (More than 80 ct) | G23: =_xlfn.XLOOKUP($A23,Load!$B:$B,Load!H:H,0,) -> Stand-Up Bag | H23: =_xlfn.XLOOKUP($A23,Load!$B:$B,Load!I:I,0,) -> Everyday Candy Shapes (like Original, Gummy bear, Fruit, Jewels, etc.) | I23: =_xlfn.XLOOKUP($A23,Load!$B:$B,Load!J:J,0,) -> Seasonal Graphics (Like Bat, Ghost, Pumpkin, Fall Leaves, Eyeballs, etc.) | J23: =_xlfn.XLOOKUP($A23,Load!$B:$B,Load!K:K,0,) -> Fun Size / Treat Size | K23: =_xlfn.XLOOKUP($A23,Load!$B:$B,Load!L:L,0,) -> Regular/Original Wrapping | L23: =_xlfn.XLOOKUP($A23,Load!$B:$B,Load!M:M,0,) -> Multiple Brands / Variety Flavors or Form
A24: Nerds Halloween Assorted Variety Bag, 70 Pieces, 32.21 Oz | B24: =_xlfn.XLOOKUP($A24,Load!$B:$B,Load!C:C,0,) -> Nerds | C24: =_xlfn.XLOOKUP($A24,Load!$B:$B,Load!D:D,0,) -> Non-Chocolate Candy Only | D24: =_xlfn.XLOOKUP($A24,Load!$B:$B,Load!E:E,0,) -> Sweet | E24: =_xlfn.XLOOKUP($A24,Load!$B:$B,Load!F:F,0,) -> Mixed / Combo Packs (Gummy, Chewy, Taffy, etc.) | F24: =_xlfn.XLOOKUP($A24,Load!$B:$B,Load!G:G,0,) -> Medium Multipack (40–80 ct) | G24: =_xlfn.XLOOKUP($A24,Load!$B:$B,Load!H:H,0,) -> Stand-Up Bag | H24: =_xlfn.XLOOKUP($A24,Load!$B:$B,Load!I:I,0,) -> Everyday Candy Shapes (like Original, Gummy bear, Fruit, Jewels, etc.) | I24: =_xlfn.XLOOKUP($A24,Load!$B:$B,Load!J:J,0,) -> Seasonal Graphics (Like Bat, Ghost, Pumpkin, Fall Leaves, Eyeballs, etc.) | J24: =_xlfn.XLOOKUP($A24,Load!$B:$B,Load!K:K,0,) -> Variety Candy Sizes | K24: =_xlfn.XLOOKUP($A24,Load!$B:$B,Load!L:L,0,) -> Regular/Original Wrapping | L24: =_xlfn.XLOOKUP($A24,Load!$B:$B,Load!M:M,0,) -> Single Brand / Variety Flavors or Form
A25: Tootsie Caramel Apple Lollipops, Green Apple Flavored, 6.82 oz | B25: =_xlfn.XLOOKUP($A25,Load!$B:$B,Load!C:C,0,) -> Tootsie | C25: =_xlfn.XLOOKUP($A25,Load!$B:$B,Load!D:D,0,) -> Non-Chocolate Candy Only | D25: =_xlfn.XLOOKUP($A25,Load!$B:$B,Load!E:E,0,) -> Fall / Seasonal Flavors (pumpkin spice, caramel apple, candy corn) | E25: =_xlfn.XLOOKUP($A25,Load!$B:$B,Load!F:F,0,) -> Lollipop (regular or lollipop rings) | F25: =_xlfn.XLOOKUP($A25,Load!$B:$B,Load!G:G,0,) -> Single Pack | G25: =_xlfn.XLOOKUP($A25,Load!$B:$B,Load!H:H,0,) -> Laydown Bag | H25: =_xlfn.XLOOKUP($A25,Load!$B:$B,Load!I:I,0,) -> Everyday Candy Shapes (like Original, Gummy bear, Fruit, Jewels, etc.) | I25: =_xlfn.XLOOKUP($A25,Load!$B:$B,Load!J:J,0,) -> Seasonal Graphics (Like Bat, Ghost, Pumpkin, Fall Leaves, Eyeballs, etc.) | J25: =_xlfn.XLOOKUP($A25,Load!$B:$B,Load!K:K,0,) -> Regular Lollipop size (on sticks or rings) | K25: =_xlfn.XLOOKUP($A25,Load!$B:$B,Load!L:L,0,) -> Regular/Original Wrapping | L25: =_xlfn.XLOOKUP($A25,Load!$B:$B,Load!M:M,0,) -> Single Brand / Single Flavor or Form
A26: Mars Ghoulish Green, Halloween Variety Pack Candy, Fun Size, 80 pcs. | B26: =_xlfn.XLOOKUP($A26,Load!$B:$B,Load!C:C,0,) -> Mars Variety Pack | C26: =_xlfn.XLOOKUP($A26,Load!$B:$B,Load!D:D,0,) -> Mix of Chocolate and Non-Chocolate Candy | D26: =_xlfn.XLOOKUP($A26,Load!$B:$B,Load!E:E,0,) -> Variety / Mixed Flavors (Fruity, Sour, Seasonal Flavors) | E26: =_xlfn.XLOOKUP($A26,Load!$B:$B,Load!F:F,0,) -> Mixed / Combo Packs (Gummy, Chewy, Taffy, etc.) | F26: =_xlfn.XLOOKUP($A26,Load!$B:$B,Load!G:G,0,) -> Medium Multipack (40–80 ct) | G26: =_xlfn.XLOOKUP($A26,Load!$B:$B,Load!H:H,0,) -> Stand-Up Bag | H26: =_xlfn.XLOOKUP($A26,Load!$B:$B,Load!I:I,0,) -> Everyday Candy Shapes (like Original, Gummy bear, Fruit, Jewels, etc.) | I26: =_xlfn.XLOOKUP($A26,Load!$B:$B,Load!J:J,0,) -> Seasonal Graphics (Like Bat, Ghost, Pumpkin, Fall Leaves, Eyeballs, etc.) | J26: =_xlfn.XLOOKUP($A26,Load!$B:$B,Load!K:K,0,) -> Fun Size / Treat Size | K26: =_xlfn.XLOOKUP($A26,Load!$B:$B,Load!L:L,0,) -> Regular/Original Wrapping | L26: =_xlfn.XLOOKUP($A26,Load!$B:$B,Load!M:M,0,) -> Multiple Brands / Variety Flavors or Form
B27: =_xlfn.XLOOKUP($A27,Load!$B:$B,Load!C:C,0,) -> 0 | C27: =_xlfn.XLOOKUP($A27,Load!$B:$B,Load!D:D,0,) -> 0 | D27: =_xlfn.XLOOKUP($A27,Load!$B:$B,Load!E:E,0,) -> 0 | E27: =_xlfn.XLOOKUP($A27,Load!$B:$B,Load!F:F,0,) -> 0 | F27: =_xlfn.XLOOKUP($A27,Load!$B:$B,Load!G:G,0,) -> 0 | G27: =_xlfn.XLOOKUP($A27,Load!$B:$B,Load!H:H,0,) -> 0 | H27: =_xlfn.XLOOKUP($A27,Load!$B:$B,Load!I:I,0,) -> 0 | I27: =_xlfn.XLOOKUP($A27,Load!$B:$B,Load!J:J,0,) -> 0 | J27: =_xlfn.XLOOKUP($A27,Load!$B:$B,Load!K:K,0,) -> 0 | K27: =_xlfn.XLOOKUP($A27,Load!$B:$B,Load!L:L,0,) -> 0 | L27: =_xlfn.XLOOKUP($A27,Load!$B:$B,Load!M:M,0,) -> 0
B28: =_xlfn.XLOOKUP($A28,Load!$B:$B,Load!C:C,0,) -> 0 | C28: =_xlfn.XLOOKUP($A28,Load!$B:$B,Load!D:D,0,) -> 0 | D28: =_xlfn.XLOOKUP($A28,Load!$B:$B,Load!E:E,0,) -> 0 | E28: =_xlfn.XLOOKUP($A28,Load!$B:$B,Load!F:F,0,) -> 0 | F28: =_xlfn.XLOOKUP($A28,Load!$B:$B,Load!G:G,0,) -> 0 | G28: =_xlfn.XLOOKUP($A28,Load!$B:$B,Load!H:H,0,) -> 0 | H28: =_xlfn.XLOOKUP($A28,Load!$B:$B,Load!I:I,0,) -> 0 | I28: =_xlfn.XLOOKUP($A28,Load!$B:$B,Load!J:J,0,) -> 0 | J28: =_xlfn.XLOOKUP($A28,Load!$B:$B,Load!K:K,0,) -> 0 | K28: =_xlfn.XLOOKUP($A28,Load!$B:$B,Load!L:L,0,) -> 0 | L28: =_xlfn.XLOOKUP($A28,Load!$B:$B,Load!M:M,0,) -> 0
B29: =_xlfn.XLOOKUP($A29,Load!$B:$B,Load!C:C,0,) -> 0 | C29: =_xlfn.XLOOKUP($A29,Load!$B:$B,Load!D:D,0,) -> 0 | D29: =_xlfn.XLOOKUP($A29,Load!$B:$B,Load!E:E,0,) -> 0 | E29: =_xlfn.XLOOKUP($A29,Load!$B:$B,Load!F:F,0,) -> 0 | F29: =_xlfn.XLOOKUP($A29,Load!$B:$B,Load!G:G,0,) -> 0 | G29: =_xlfn.XLOOKUP($A29,Load!$B:$B,Load!H:H,0,) -> 0 | H29: =_xlfn.XLOOKUP($A29,Load!$B:$B,Load!I:I,0,) -> 0 | I29: =_xlfn.XLOOKUP($A29,Load!$B:$B,Load!J:J,0,) -> 0 | J29: =_xlfn.XLOOKUP($A29,Load!$B:$B,Load!K:K,0,) -> 0 | K29: =_xlfn.XLOOKUP($A29,Load!$B:$B,Load!L:L,0,) -> 0 | L29: =_xlfn.XLOOKUP($A29,Load!$B:$B,Load!M:M,0,) -> 0
A30: SOUR PATCH KIDS Zombie Orange & Purple Soft & Chewy Halloween Candy, 3.5 oz | B30: =_xlfn.XLOOKUP($A30,Load!$B:$B,Load!C:C,0,) -> Sour Patch Kids | C30: =_xlfn.XLOOKUP($A30,Load!$B:$B,Load!D:D,0,) -> Non-Chocolate Candy Only | D30: =_xlfn.XLOOKUP($A30,Load!$B:$B,Load!E:E,0,) -> Fruit Flavor (Cherry, Grape, Apple, Citrus, Tropical Fruit) | E30: =_xlfn.XLOOKUP($A30,Load!$B:$B,Load!F:F,0,) -> Chewy | F30: =_xlfn.XLOOKUP($A30,Load!$B:$B,Load!G:G,0,) -> Small Multipack (Less than 40 ct) | G30: =_xlfn.XLOOKUP($A30,Load!$B:$B,Load!H:H,0,) -> Box (theatre box, gift box, carton) | H30: =_xlfn.XLOOKUP($A30,Load!$B:$B,Load!I:I,0,) -> Everyday Candy Shapes (like Original, Gummy bear, Fruit, Jewels, etc.) | I30: =_xlfn.XLOOKUP($A30,Load!$B:$B,Load!J:J,0,) -> Seasonal Graphics (Like Bat, Ghost, Pumpkin, Fall Leaves, Eyeballs, etc.) | J30: =_xlfn.XLOOKUP($A30,Load!$B:$B,Load!K:K,0,) -> Small Pieces (Tiny bite size candies) | K30: =_xlfn.XLOOKUP($A30,Load!$B:$B,Load!L:L,0,) -> Unwrapped | L30: =_xlfn.XLOOKUP($A30,Load!$B:$B,Load!M:M,0,) -> Single Brand / Variety Flavors or Form
A31: Brach’s Mellowcreme Caramel Apple Halloween Candy Corn, 9 Ozs, Laydown Bag | B31: =_xlfn.XLOOKUP($A31,Load!$B:$B,Load!C:C,0,) -> Brach's | C31: =_xlfn.XLOOKUP($A31,Load!$B:$B,Load!D:D,0,) -> Non-Chocolate Candy Only | D31: =_xlfn.XLOOKUP($A31,Load!$B:$B,Load!E:E,0,) -> Fall / Seasonal Flavors (pumpkin spice, caramel apple, candy corn) | E31: =_xlfn.XLOOKUP($A31,Load!$B:$B,Load!F:F,0,) -> Candy Pieces / Bites | F31: =_xlfn.XLOOKUP($A31,Load!$B:$B,Load!G:G,0,) -> Single Pack | G31: =_xlfn.XLOOKUP($A31,Load!$B:$B,Load!H:H,0,) -> Laydown Bag | H31: =_xlfn.XLOOKUP($A31,Load!$B:$B,Load!I:I,0,) -> Seasonal Shapes (like pumpkins, candy corn, ghost, bats, etc.) | I31: =_xlfn.XLOOKUP($A31,Load!$B:$B,Load!J:J,0,) -> Seasonal Graphics (Like Bat, Ghost, Pumpkin, Fall Leaves, Eyeballs, etc.) | J31: =_xlfn.XLOOKUP($A31,Load!$B:$B,Load!K:K,0,) -> Small Pieces (Tiny bite size candies) | K31: =_xlfn.XLOOKUP($A31,Load!$B:$B,Load!L:L,0,) -> Unwrapped | L31: =_xlfn.XLOOKUP($A31,Load!$B:$B,Load!M:M,0,) -> Single Brand / Single Flavor or Form
A32: Trolli Mini Sour Brite Crawlers 3.5 Oz Sharepack | B32: =_xlfn.XLOOKUP($A32,Load!$B:$B,Load!C:C,0,) -> Trolli | C32: =_xlfn.XLOOKUP($A32,Load!$B:$B,Load!D:D,0,) -> Non-Chocolate Candy Only | D32: =_xlfn.XLOOKUP($A32,Load!$B:$B,Load!E:E,0,) -> Variety / Mixed Flavors (Fruity, Sour, Seasonal Flavors) | E32: =_xlfn.XLOOKUP($A32,Load!$B:$B,Load!F:F,0,) -> Gummy | F32: =_xlfn.XLOOKUP($A32,Load!$B:$B,Load!G:G,0,) -> Small Multipack (Less than 40 ct) | G32: =_xlfn.XLOOKUP($A32,Load!$B:$B,Load!H:H,0,) -> Laydown Bag | H32: =_xlfn.XLOOKUP($A32,Load!$B:$B,Load!I:I,0,) -> Everyday Candy Shapes (like Original, Gummy bear, Fruit, Jewels, etc.) | I32: =_xlfn.XLOOKUP($A32,Load!$B:$B,Load!J:J,0,) -> Seasonal Graphics (Like Bat, Ghost, Pumpkin, Fall Leaves, Eyeballs, etc.) | J32: =_xlfn.XLOOKUP($A32,Load!$B:$B,Load!K:K,0,) -> Small Pieces (Tiny bite size candies) | K32: =_xlfn.XLOOKUP($A32,Load!$B:$B,Load!L:L,0,) -> Unwrapped | L32: =_xlfn.XLOOKUP($A32,Load!$B:$B,Load!M:M,0,) -> Single Brand / Variety Flavors or Form
B33: =_xlfn.XLOOKUP($A33,Load!$B:$B,Load!C:C,0,) -> 0 | C33: =_xlfn.XLOOKUP($A33,Load!$B:$B,Load!D:D,0,) -> 0 | D33: =_xlfn.XLOOKUP($A33,Load!$B:$B,Load!E:E,0,) -> 0 | E33: =_xlfn.XLOOKUP($A33,Load!$B:$B,Load!F:F,0,) -> 0 | F33: =_xlfn.XLOOKUP($A33,Load!$B:$B,Load!G:G,0,) -> 0 | G33: =_xlfn.XLOOKUP($A33,Load!$B:$B,Load!H:H,0,) -> 0 | H33: =_xlfn.XLOOKUP($A33,Load!$B:$B,Load!I:I,0,) -> 0 | I33: =_xlfn.XLOOKUP($A33,Load!$B:$B,Load!J:J,0,) -> 0 | J33: =_xlfn.XLOOKUP($A33,Load!$B:$B,Load!K:K,0,) -> 0 | K33: =_xlfn.XLOOKUP($A33,Load!$B:$B,Load!L:L,0,) -> 0 | L33: =_xlfn.XLOOKUP($A33,Load!$B:$B,Load!M:M,0,) -> 0
B34: =_xlfn.XLOOKUP($A34,Load!$B:$B,Load!C:C,0,) -> 0 | C34: =_xlfn.XLOOKUP($A34,Load!$B:$B,Load!D:D,0,) -> 0 | D34: =_xlfn.XLOOKUP($A34,Load!$B:$B,Load!E:E,0,) -> 0 | E34: =_xlfn.XLOOKUP($A34,Load!$B:$B,Load!F:F,0,) -> 0 | F34: =_xlfn.XLOOKUP($A34,Load!$B:$B,Load!G:G,0,) -> 0 | G34: =_xlfn.XLOOKUP($A34,Load!$B:$B,Load!H:H,0,) -> 0 | H34: =_xlfn.XLOOKUP($A34,Load!$B:$B,Load!I:I,0,) -> 0 | I34: =_xlfn.XLOOKUP($A34,Load!$B:$B,Load!J:J,0,) -> 0 | J34: =_xlfn.XLOOKUP($A34,Load!$B:$B,Load!K:K,0,) -> 0 | K34: =_xlfn.XLOOKUP($A34,Load!$B:$B,Load!L:L,0,) -> 0 | L34: =_xlfn.XLOOKUP($A34,Load!$B:$B,Load!M:M,0,) -> 0
B35: =_xlfn.XLOOKUP($A35,Load!$B:$B,Load!C:C,0,) -> 0 | C35: =_xlfn.XLOOKUP($A35,Load!$B:$B,Load!D:D,0,) -> 0 | D35: =_xlfn.XLOOKUP($A35,Load!$B:$B,Load!E:E,0,) -> 0 | E35: =_xlfn.XLOOKUP($A35,Load!$B:$B,Load!F:F,0,) -> 0 | F35: =_xlfn.XLOOKUP($A35,Load!$B:$B,Load!G:G,0,) -> 0 | G35: =_xlfn.XLOOKUP($A35,Load!$B:$B,Load!H:H,0,) -> 0 | H35: =_xlfn.XLOOKUP($A35,Load!$B:$B,Load!I:I,0,) -> 0 | I35: =_xlfn.XLOOKUP($A35,Load!$B:$B,Load!J:J,0,) -> 0 | J35: =_xlfn.XLOOKUP($A35,Load!$B:$B,Load!K:K,0,) -> 0 | K35: =_xlfn.XLOOKUP($A35,Load!$B:$B,Load!L:L,0,) -> 0 | L35: =_xlfn.XLOOKUP($A35,Load!$B:$B,Load!M:M,0,) -> 0
B36: =_xlfn.XLOOKUP($A36,Load!$B:$B,Load!C:C,0,) -> 0 | C36: =_xlfn.XLOOKUP($A36,Load!$B:$B,Load!D:D,0,) -> 0 | D36: =_xlfn.XLOOKUP($A36,Load!$B:$B,Load!E:E,0,) -> 0 | E36: =_xlfn.XLOOKUP($A36,Load!$B:$B,Load!F:F,0,) -> 0 | F36: =_xlfn.XLOOKUP($A36,Load!$B:$B,Load!G:G,0,) -> 0 | G36: =_xlfn.XLOOKUP($A36,Load!$B:$B,Load!H:H,0,) -> 0 | H36: =_xlfn.XLOOKUP($A36,Load!$B:$B,Load!I:I,0,) -> 0 | I36: =_xlfn.XLOOKUP($A36,Load!$B:$B,Load!J:J,0,) -> 0 | J36: =_xlfn.XLOOKUP($A36,Load!$B:$B,Load!K:K,0,) -> 0 | K36: =_xlfn.XLOOKUP($A36,Load!$B:$B,Load!L:L,0,) -> 0 | L36: =_xlfn.XLOOKUP($A36,Load!$B:$B,Load!M:M,0,) -> 0
B37: =_xlfn.XLOOKUP($A37,Load!$B:$B,Load!C:C,0,) -> 0 | C37: =_xlfn.XLOOKUP($A37,Load!$B:$B,Load!D:D,0,) -> 0 | D37: =_xlfn.XLOOKUP($A37,Load!$B:$B,Load!E:E,0,) -> 0 | E37: =_xlfn.XLOOKUP($A37,Load!$B:$B,Load!F:F,0,) -> 0 | F37: =_xlfn.XLOOKUP($A37,Load!$B:$B,Load!G:G,0,) -> 0 | G37: =_xlfn.XLOOKUP($A37,Load!$B:$B,Load!H:H,0,) -> 0 | H37: =_xlfn.XLOOKUP($A37,Load!$B:$B,Load!I:I,0,) -> 0 | I37: =_xlfn.XLOOKUP($A37,Load!$B:$B,Load!J:J,0,) -> 0 | J37: =_xlfn.XLOOKUP($A37,Load!$B:$B,Load!K:K,0,) -> 0 | K37: =_xlfn.XLOOKUP($A37,Load!$B:$B,Load!L:L,0,) -> 0 | L37: =_xlfn.XLOOKUP($A37,Load!$B:$B,Load!M:M,0,) -> 0
A38: JOLLY RANCHER and TWIZZLERS Assorted Fruit Flavored Candy Party Pack, Halloween Candy, 43.03 oz | B38: =_xlfn.XLOOKUP($A38,Load!$B:$B,Load!C:C,0,) -> Hershey's Variety Pack | C38: =_xlfn.XLOOKUP($A38,Load!$B:$B,Load!D:D,0,) -> Non-Chocolate Candy Only | D38: =_xlfn.XLOOKUP($A38,Load!$B:$B,Load!E:E,0,) -> Variety / Mixed Flavors (Fruity, Sour, Seasonal Flavors) | E38: =_xlfn.XLOOKUP($A38,Load!$B:$B,Load!F:F,0,) -> Mixed / Combo Packs (Gummy, Chewy, Taffy, etc.) | F38: =_xlfn.XLOOKUP($A38,Load!$B:$B,Load!G:G,0,) -> Large Multipack (More than 80 ct) | G38: =_xlfn.XLOOKUP($A38,Load!$B:$B,Load!H:H,0,) -> Stand-Up Bag | H38: =_xlfn.XLOOKUP($A38,Load!$B:$B,Load!I:I,0,) -> Everyday Candy Shapes (like Original, Gummy bear, Fruit, Jewels, etc.) | I38: =_xlfn.XLOOKUP($A38,Load!$B:$B,Load!J:J,0,) -> Everyday Graphics | J38: =_xlfn.XLOOKUP($A38,Load!$B:$B,Load!K:K,0,) -> Variety Candy Sizes | K38: =_xlfn.XLOOKUP($A38,Load!$B:$B,Load!L:L,0,) -> Regular/Original Wrapping | L38: =_xlfn.XLOOKUP($A38,Load!$B:$B,Load!M:M,0,) -> Multiple Brands / Variety Flavors or Form
B39: =_xlfn.XLOOKUP($A39,Load!$B:$B,Load!C:C,0,) -> 0 | C39: =_xlfn.XLOOKUP($A39,Load!$B:$B,Load!D:D,0,) -> 0 | D39: =_xlfn.XLOOKUP($A39,Load!$B:$B,Load!E:E,0,) -> 0 | E39: =_xlfn.XLOOKUP($A39,Load!$B:$B,Load!F:F,0,) -> 0 | F39: =_xlfn.XLOOKUP($A39,Load!$B:$B,Load!G:G,0,) -> 0 | G39: =_xlfn.XLOOKUP($A39,Load!$B:$B,Load!H:H,0,) -> 0 | H39: =_xlfn.XLOOKUP($A39,Load!$B:$B,Load!I:I,0,) -> 0 | I39: =_xlfn.XLOOKUP($A39,Load!$B:$B,Load!J:J,0,) -> 0 | J39: =_xlfn.XLOOKUP($A39,Load!$B:$B,Load!K:K,0,) -> 0 | K39: =_xlfn.XLOOKUP($A39,Load!$B:$B,Load!L:L,0,) -> 0 | L39: =_xlfn.XLOOKUP($A39,Load!$B:$B,Load!M:M,0,) -> 0
B40: =_xlfn.XLOOKUP($A40,Load!$B:$B,Load!C:C,0,) -> 0 | C40: =_xlfn.XLOOKUP($A40,Load!$B:$B,Load!D:D,0,) -> 0 | D40: =_xlfn.XLOOKUP($A40,Load!$B:$B,Load!E:E,0,) -> 0 | E40: =_xlfn.XLOOKUP($A40,Load!$B:$B,Load!F:F,0,) -> 0 | F40: =_xlfn.XLOOKUP($A40,Load!$B:$B,Load!G:G,0,) -> 0 | G40: =_xlfn.XLOOKUP($A40,Load!$B:$B,Load!H:H,0,) -> 0 | H40: =_xlfn.XLOOKUP($A40,Load!$B:$B,Load!I:I,0,) -> 0 | I40: =_xlfn.XLOOKUP($A40,Load!$B:$B,Load!J:J,0,) -> 0 | J40: =_xlfn.XLOOKUP($A40,Load!$B:$B,Load!K:K,0,) -> 0 | K40: =_xlfn.XLOOKUP($A40,Load!$B:$B,Load!L:L,0,) -> 0 | L40: =_xlfn.XLOOKUP($A40,Load!$B:$B,Load!M:M,0,) -> 0
...

Sheet O1_12
A1: {=_xludf.TEXTAFTER(CELL("filename",A1),"]")} -> #NAME? | B1: =ADDRESS(4,MATCH(A1,Load!#REF!,0),1,1,"Text Labels")&":"&ADDRESS(2000,MATCH(A1,Load!#REF!,0),1) -> #NAME? | D1: No changes | E1: Current List (Paste list values here to keep track of changes)
A2: {=_xlws.SORT(_xludf.UNIQUE(INDIRECT($B$1),FALSE))} -> #NAME? | B2: 1 | C2: =A2 -> #NAME? | D2: =C2=E2 -> #NAME? | E2: Dry / Oven Roasted
B3: 2 | C3: =A3 -> 0 | D3: =C3=E3 -> FALSE | E3: Honey Roasted
B4: 3 | C4: =A4 -> 0 | D4: =C4=E4 -> FALSE | E4: Oil Roasted
B5: 4 | C5: =A5 -> 0 | D5: =C5=E5 -> FALSE | E5: Raw / Unroasted
B6: 5 | C6: =A6 -> 0 | D6: =C6=E6 -> TRUE
B7: 6 | C7: =A7 -> 0 | D7: =C7=E7 -> TRUE
B8: 7 | C8: =A8 -> 0 | D8: =C8=E8 -> TRUE
B9: 8 | C9: =A9 -> 0 | D9: =C9=E9 -> TRUE
B10: 9 | C10: =A10 -> 0 | D10: =C10=E10 -> TRUE
B11: 10 | C11: =A11 -> 0 | D11: =C11=E11 -> TRUE
B12: 11 | C12: =A12 -> 0 | D12: =C12=E12 -> TRUE
B13: 12 | C13: =A13 -> 0 | D13: =C13=E13 -> TRUE
B14: 13 | C14: =A14 -> 0 | D14: =C14=E14 -> TRUE
B15: 14 | C15: =A15 -> 0 | D15: =C15=E15 -> TRUE
B16: 15 | C16: =A16 -> 0 | D16: =C16=E16 -> TRUE
B17: 16 | C17: =A17 -> 0 | D17: =C17=E17 -> TRUE
... B36: 35 | C36: =A36 -> 0 | D36: =C36=E36 -> TRUE
